<?xml version="1.0" ?>
<robot xmlns:xacro="http://www.ros.org/wiki/xacro">
<xacro:macro name="faze4" params="parent prefix *origin">
  <joint name="${prefix}base_joint" type="fixed">
    <xacro:insert_block name="origin" />
    <parent link="${parent}"/>
    <child link="${prefix}base_link" />
  </joint>
	<link
    name="${prefix}base_link">
    <inertial>
      <origin
        xyz="0.0754452420016786 0.0706653851885525 0.174716050606158"
        rpy="0 0 0" />
      <mass
        value="1.75590983031249" />
      <inertia
        ixx="0.0106901651591523"
        ixy="1.2533292416581E-05"
        ixz="-1.78802486116636E-05"
        iyy="0.0121389538778755"
        iyz="-0.0001726147454493"
        izz="0.00523087609446992" />
    </inertial>
    <visual>
      <origin
        xyz="0 0 0"
        rpy="0 0 0" />
      <geometry>
        <mesh
          filename="package://faze4_description/meshes/base_link.stl" />
      </geometry>
      <material
        name="">
        <color
          rgba="0.792156862745098 0.819607843137255 0.933333333333333 1" />
      </material>
    </visual>
    <collision>
      <origin
        xyz="0 0 0"
        rpy="0 0 0" />
      <geometry>
        <mesh
          filename="package://faze4_description/meshes/base_link.stl" />
      </geometry>
    </collision>
  </link>
  <link
    name="${prefix}link1">
    <inertial>
      <origin
        xyz="3.6594E-07 -0.12491 -0.0091222"
        rpy="0 0 0" />
      <mass
        value="1.8968" />
      <inertia
        ixx="0.011703"
        ixy="6.2683E-07"
        ixz="2.7765E-07"
        iyy="0.010005"
        iyz="-0.00096832"
        izz="0.0065158" />
    </inertial>
    <visual>
      <origin
        xyz="0 0 0"
        rpy="0 0 0" />
      <geometry>
        <mesh
          filename="package://faze4_description/meshes/rotary_base.stl" />
      </geometry>
      <material
        name="">
        <color
          rgba="0.79216 0.81961 0.93333 1" />
      </material>
    </visual>
    <collision>
      <origin
        xyz="0 0 0"
        rpy="0 0 0" />
      <geometry>
        <mesh
          filename="package://faze4_description/meshes/rotary_base.stl" />
      </geometry>
    </collision>
  </link>
  <joint
    name="${prefix}joint1"
    type="revolute">
    <origin
      xyz="0.075629 -0.21266 0.050734"
      rpy="-1.5708 0 3.142" />
    <parent
      link="${prefix}base_link" />
    <child
      link="${prefix}link1" />
    <axis
      xyz="0 -1 0" />
    <limit lower="-3.14" upper="3.14" effort="1000.0" velocity="0.3"/>
  </joint>
  <link
    name="${prefix}link2">
    <inertial>
      <origin
        xyz="0.11187 -0.011704 0.007695"
        rpy="0 0 0" />
      <mass
        value="3.097" />
      <inertia
        ixx="0.011686"
        ixy="0.0012432"
        ixz="-0.0018781"
        iyy="0.03891"
        iyz="-5.4012E-05"
        izz="0.032612" />
    </inertial>
    <visual>
      <origin
        xyz="0 0 0"
        rpy="0 0 0" />
      <geometry>
        <mesh
          filename="package://faze4_description/meshes/nadlaktica.stl" />
      </geometry>
      <material
        name="">
        <color
          rgba="0.79216 0.81961 0.93333 1" />
      </material>
    </visual>
    <collision>
      <origin
        xyz="0 0 0"
        rpy="0 0 0" />
      <geometry>
        <mesh
          filename="package://faze4_description/meshes/nadlaktica.stl" />
      </geometry>
    </collision>
  </link>
  <joint
    name="${prefix}joint2"
    type="revolute">
    <origin
      xyz="0 -0.20182 0"
      rpy="2.7756E-15 -1.3878E-15 -1.4" />
    <parent
      link="${prefix}link1" />
    <child
      link="${prefix}link2" />
    <axis
      xyz="0 0 1" />
    <limit lower="0" upper="2.35" effort="1000.0" velocity="0.3"/>
  </joint>
  <link
    name="${prefix}link3">
    <inertial>
      <origin
        xyz="0.020310022580536 -0.0354589471585284 0.00171229454365077"
        rpy="0 0 0" />
      <mass
        value="1.2726491805247" />
      <inertia
        ixx="0.00430935066273582"
        ixy="-0.000472663673983171"
        ixz="2.10793692092687E-05"
        iyy="0.00388873322685888"
        iyz="-0.000102922808916268"
        izz="0.00512549454697952" />
    </inertial>
    <visual>
      <origin
        xyz="0 0 0"
        rpy="0 0 0" />
      <geometry>
        <mesh
          filename="package://faze4_description/meshes/lakat.stl" />
      </geometry>
      <material
        name="">
        <color
          rgba="0.792156862745098 0.819607843137255 0.933333333333333 1" />
      </material>
    </visual>
    <collision>
      <origin
        xyz="0 0 0"
        rpy="0 0 0" />
      <geometry>
        <mesh
          filename="package://faze4_description/meshes/lakat.stl" />
      </geometry>
    </collision>
  </link>
  <joint
    name="${prefix}joint3"
    type="revolute">
    <origin
      xyz="0.32 0 0"
      rpy="3.1416 0 -3.3" />
    <parent
      link="${prefix}link2" />
    <child
      link="${prefix}link3" />
    <axis
      xyz="0 0 -1" />
    <limit lower="-0.3" upper="2.61799" effort="1000.0" velocity="0.3"/>
  </joint>
  <link
    name="${prefix}link4">
    <inertial>
      <origin
        xyz="0.015666 0.10444 0.04524"
        rpy="0 0 0" />
      <mass
        value="0.8658" />
      <inertia
        ixx="0.0043737"
        ixy="-0.00033248"
        ixz="-0.00029637"
        iyy="0.0017275"
        iyz="-0.0011009"
        izz="0.0039233" />
    </inertial>
    <visual>
      <origin
        xyz="0 0 0"
        rpy="0 0 0" />
      <geometry>
        <mesh
          filename="package://faze4_description/meshes/podlaktica.stl" />
      </geometry>
      <material
        name="">
        <color
          rgba="0.79216 0.81961 0.93333 1" />
      </material>
    </visual>
    <collision>
      <origin
        xyz="0 0 0"
        rpy="0 0 0" />
      <geometry>
        <mesh
          filename="package://faze4_description/meshes/podlaktica.stl" />
      </geometry>
    </collision>
  </link>
  <joint
    name="${prefix}joint4"
    type="revolute">
    <origin
      xyz="0 -0.0735 0"
      rpy="-0.5648 -0.675 1.7809" />
    <parent
      link="${prefix}link3" />
    <child
      link="${prefix}link4" />
    <axis
      xyz="0.14804 0.90477 0.39934" />
    <limit lower="-2.35" upper="2.35" effort="1000.0" velocity="0.3"/>
  </joint>
  <link
    name="${prefix}link5">
    <inertial>
      <origin
        xyz="0.00102127447654127 0.00173769308862193 -0.00307332521672926"
        rpy="0 0 0" />
      <mass
        value="0.195660541483626" />
      <inertia
        ixx="0.000196163267087824"
        ixy="-1.19915207726741E-07"
        ixz="-4.99910323817217E-07"
        iyy="0.000195263940589931"
        iyz="9.07364788265256E-06"
        izz="0.000136132402412911" />
    </inertial>
    <visual>
      <origin
        xyz="0 0 0"
        rpy="0 0 0" />
      <geometry>
        <mesh
          filename="package://faze4_description/meshes/saka.stl" />
      </geometry>
      <material
        name="">
        <color
          rgba="0.792156862745098 0.819607843137255 0.933333333333333 1" />
      </material>
    </visual>
    <collision>
      <origin
        xyz="0 0 0"
        rpy="0 0 0" />
      <geometry>
        <mesh
          filename="package://faze4_description/meshes/saka.stl" />
      </geometry>
    </collision>
  </link>
  <joint
    name="${prefix}joint5"
    type="revolute">
    <origin
      xyz="0.037114 0.22683 0.10011"
      rpy="2.16 -0.74045 -0.57161" />
    <parent
      link="${prefix}link4" />
    <child
      link="${prefix}link5" />
    <axis
      xyz="-1 0 0" />
    <limit lower="-2.0944" upper="2.0944" effort="1000.0" velocity="0.3"/>
  </joint>
  <link
    name="${prefix}link6">
    <inertial>
      <origin
        xyz="0.00017222 0.00017758 0.00947"
        rpy="0 0 0" />
      <mass
        value="0.020284" />
      <inertia
        ixx="3.4622E-06"
        ixy="-9.927E-08"
        ixz="-2.2616E-08"
        iyy="3.4561E-06"
        iyz="-2.332E-08"
        izz="6.3508E-06" />
    </inertial>
    <visual>
      <origin
        xyz="0 0 0"
        rpy="0 0 0.77" />
      <geometry>
        <mesh
          filename="package://faze4_description/meshes/hvataljka.stl" />
      </geometry>
      <material
        name="">
        <color
          rgba="0.79216 0.81961 0.93333 1" />
      </material>
    </visual>
    <collision>
      <origin
        xyz="0 0 0"
        rpy="0 0 0.77" />
      <geometry>
        <mesh
          filename="package://faze4_description/meshes/hvataljka.stl" />
      </geometry>
    </collision>
  </link>
  <joint
    name="${prefix}joint6"
    type="continuous">
    <origin
      xyz="0 0 -0.042312"
      rpy="-3.1416 0 0" />
    <parent
      link="${prefix}link5" />
    <child
      link="${prefix}link6" />
    <axis
      xyz="0 0 1" />
  </joint>
  <link
    name="${prefix}link7">
    <inertial>
      <origin
        xyz="0 0 0"
        rpy="0 0 0" />
      <mass
        value="0.011" />
      <inertia
        ixx="1.5488534576213277e-05"
        ixy="0"
        ixz="0"
        iyy="1.5488915081958018e-05"
        iyz="0"
        izz="4.689528721728688e-07" />
    </inertial>
    <visual>
      <origin
        xyz="0 0 0"
        rpy="0 0 0" />
      <geometry>
        <mesh
          filename="package://faze4_description/meshes/marker.stl" />
      </geometry>
      <material
        name="">
        <color
          rgba="0.792156862745098 0.819607843137255 0.933333333333333 1" />
      </material>
    </visual>
    <collision>
      <origin
        xyz="0 0 0"
        rpy="0 0 0" />
      <geometry>
        <mesh
          filename="package://faze4_description/meshes/marker.stl" />
      </geometry>
    </collision>
  </link>
  <joint
    name="${prefix}joint7"
    type="fixed">
    <origin
      xyz="0 0.1 0.024"
      rpy="1.57 0 0" />
    <parent
      link="${prefix}link6" />
    <child
      link="${prefix}link7" />
  </joint>
</xacro:macro>
</robot>
